<?xml version="1.0" encoding="UTF-8"?>
<!-- Generated by org.testng.reporters.JUnitReportReporter -->
<testsuite skipped="2" hostname="DESKTOP-5V3Q9AB" name="com.training.sanity.tests.LoginTestAsgnmt1" tests="3" failures="1" timestamp="13 Mar 2020 11:22:44 GMT" time="27.083" errors="0">
  <testcase name="validLoginTest" time="0.000" classname="com.training.sanity.tests.LoginTestAsgnmt1">
    <skipped/>
  </testcase> <!-- validLoginTest -->
  <testcase name="validrocoverPasswordTest" time="0.000" classname="com.training.sanity.tests.LoginTestAsgnmt1">
    <skipped/>
  </testcase> <!-- validrocoverPasswordTest -->
  <testcase name="validRegTest" time="27.083" classname="com.training.sanity.tests.LoginTestAsgnmt1">
    <failure type="java.lang.AssertionError" message="expected [You have successfully registered to Real Estate. We have emailed your password to the email address you entered.] but found [An account exists with this email address.]">
      <![CDATA[java.lang.AssertionError: expected [You have successfully registered to Real Estate. We have emailed your password to the email address you entered.] but found [An account exists with this email address.]
	at org.testng.Assert.fail(Assert.java:93)
	at org.testng.Assert.failNotEquals(Assert.java:512)
	at org.testng.Assert.assertEqualsImpl(Assert.java:134)
	at org.testng.Assert.assertEquals(Assert.java:115)
	at org.testng.Assert.assertEquals(Assert.java:189)
	at org.testng.Assert.assertEquals(Assert.java:199)
	at com.training.pom.RegisterPOM.RegisterNotificmsg(RegisterPOM.java:63)
	at com.training.sanity.tests.LoginTestAsgnmt1.validRegTest(LoginTestAsgnmt1.java:67)
	at sun.reflect.NativeMethodAccessorImpl.invoke0(Native Method)
	at sun.reflect.NativeMethodAccessorImpl.invoke(Unknown Source)
	at sun.reflect.DelegatingMethodAccessorImpl.invoke(Unknown Source)
	at java.lang.reflect.Method.invoke(Unknown Source)
	at org.testng.internal.MethodInvocationHelper.invokeMethod(MethodInvocationHelper.java:108)
	at org.testng.internal.Invoker.invokeMethod(Invoker.java:661)
	at org.testng.internal.Invoker.invokeTestMethod(Invoker.java:869)
	at org.testng.internal.Invoker.invokeTestMethods(Invoker.java:1193)
	at org.testng.internal.TestMethodWorker.invokeTestMethods(TestMethodWorker.java:126)
	at org.testng.internal.TestMethodWorker.run(TestMethodWorker.java:109)
	at org.testng.TestRunner.privateRun(TestRunner.java:744)
	at org.testng.TestRunner.run(TestRunner.java:602)
	at org.testng.SuiteRunner.runTest(SuiteRunner.java:380)
	at org.testng.SuiteRunner.runSequentially(SuiteRunner.java:375)
	at org.testng.SuiteRunner.privateRun(SuiteRunner.java:340)
	at org.testng.SuiteRunner.run(SuiteRunner.java:289)
	at org.testng.SuiteRunnerWorker.runSuite(SuiteRunnerWorker.java:52)
	at org.testng.SuiteRunnerWorker.run(SuiteRunnerWorker.java:86)
	at org.testng.TestNG.runSuitesSequentially(TestNG.java:1301)
	at org.testng.TestNG.runSuitesLocally(TestNG.java:1226)
	at org.testng.TestNG.runSuites(TestNG.java:1144)
	at org.testng.TestNG.run(TestNG.java:1115)
	at org.testng.remote.AbstractRemoteTestNG.run(AbstractRemoteTestNG.java:115)
	at org.testng.remote.RemoteTestNG.initAndRun(RemoteTestNG.java:251)
	at org.testng.remote.RemoteTestNG.main(RemoteTestNG.java:77)
]]>
    </failure>
  </testcase> <!-- validRegTest -->
</testsuite> <!-- com.training.sanity.tests.LoginTestAsgnmt1 -->
